[2023-04-02 15:55:22,925] {taskinstance.py:877} INFO - Dependencies all met for <TaskInstance: dag_weather_etl_v01.get_aemet_data 2023-03-26T00:00:00+00:00 [queued]>
[2023-04-02 15:55:23,085] {taskinstance.py:877} INFO - Dependencies all met for <TaskInstance: dag_weather_etl_v01.get_aemet_data 2023-03-26T00:00:00+00:00 [queued]>
[2023-04-02 15:55:23,092] {taskinstance.py:1068} INFO - 
--------------------------------------------------------------------------------
[2023-04-02 15:55:23,096] {taskinstance.py:1069} INFO - Starting attempt 2 of 6
[2023-04-02 15:55:23,099] {taskinstance.py:1070} INFO - 
--------------------------------------------------------------------------------
[2023-04-02 15:55:23,435] {taskinstance.py:1089} INFO - Executing <Task(_PythonDecoratedOperator): get_aemet_data> on 2023-03-26T00:00:00+00:00
[2023-04-02 15:55:24,328] {standard_task_runner.py:52} INFO - Started process 75 to run task
[2023-04-02 15:55:25,128] {standard_task_runner.py:76} INFO - Running: ['airflow', 'tasks', 'run', 'dag_weather_etl_v01', 'get_aemet_data', '2023-03-26T00:00:00+00:00', '--job-id', '99', '--pool', 'default_pool', '--raw', '--subdir', 'DAGS_FOLDER/dag_etl_weather.py', '--cfg-path', '/tmp/tmpvbu6x58j', '--error-file', '/tmp/tmphr_no17f']
[2023-04-02 15:55:25,202] {standard_task_runner.py:77} INFO - Job 99: Subtask get_aemet_data
[2023-04-02 15:55:26,690] {logging_mixin.py:104} INFO - Running <TaskInstance: dag_weather_etl_v01.get_aemet_data 2023-03-26T00:00:00+00:00 [running]> on host ab4c74a9709c
[2023-04-02 15:55:28,285] {taskinstance.py:1283} INFO - Exporting the following env vars:
AIRFLOW_CTX_DAG_OWNER=Mario
AIRFLOW_CTX_DAG_ID=dag_weather_etl_v01
AIRFLOW_CTX_TASK_ID=get_aemet_data
AIRFLOW_CTX_EXECUTION_DATE=2023-03-26T00:00:00+00:00
AIRFLOW_CTX_DAG_RUN_ID=scheduled__2023-03-26T00:00:00+00:00
[2023-04-02 15:55:33,337] {xcom.py:238} ERROR - Could not serialize the XCom value into JSON. If you are using pickles instead of JSON for XCom, then you need to enable pickle support for XCom in your airflow config.
[2023-04-02 15:55:33,389] {taskinstance.py:1482} ERROR - Task failed with exception
Traceback (most recent call last):
  File "/home/airflow/.local/lib/python3.6/site-packages/airflow/models/taskinstance.py", line 1138, in _run_raw_task
    self._prepare_and_execute_task_with_callbacks(context, task)
  File "/home/airflow/.local/lib/python3.6/site-packages/airflow/models/taskinstance.py", line 1311, in _prepare_and_execute_task_with_callbacks
    result = self._execute_task(context, task_copy)
  File "/home/airflow/.local/lib/python3.6/site-packages/airflow/models/taskinstance.py", line 1344, in _execute_task
    self.xcom_push(key=XCOM_RETURN_KEY, value=result)
  File "/home/airflow/.local/lib/python3.6/site-packages/airflow/utils/session.py", line 70, in wrapper
    return func(*args, session=session, **kwargs)
  File "/home/airflow/.local/lib/python3.6/site-packages/airflow/models/taskinstance.py", line 1928, in xcom_push
    session=session,
  File "/home/airflow/.local/lib/python3.6/site-packages/airflow/utils/session.py", line 67, in wrapper
    return func(*args, **kwargs)
  File "/home/airflow/.local/lib/python3.6/site-packages/airflow/models/xcom.py", line 88, in set
    value = XCom.serialize_value(value)
  File "/home/airflow/.local/lib/python3.6/site-packages/airflow/models/xcom.py", line 235, in serialize_value
    return json.dumps(value).encode('UTF-8')
  File "/usr/local/lib/python3.6/json/__init__.py", line 231, in dumps
    return _default_encoder.encode(obj)
  File "/usr/local/lib/python3.6/json/encoder.py", line 199, in encode
    chunks = self.iterencode(o, _one_shot=True)
  File "/usr/local/lib/python3.6/json/encoder.py", line 257, in iterencode
    return _iterencode(o, 0)
  File "/usr/local/lib/python3.6/json/encoder.py", line 180, in default
    o.__class__.__name__)
TypeError: Object of type 'DataFrame' is not JSON serializable
[2023-04-02 15:55:33,691] {taskinstance.py:1532} INFO - Marking task as UP_FOR_RETRY. dag_id=dag_weather_etl_v01, task_id=get_aemet_data, execution_date=20230326T000000, start_date=20230402T155522, end_date=20230402T155533
[2023-04-02 15:55:36,202] {local_task_job.py:188} WARNING - State of this instance has been externally set to up_for_retry. Terminating instance.
[2023-04-02 15:55:36,473] {process_utils.py:100} INFO - Sending Signals.SIGTERM to GPID 75
[2023-04-02 15:55:36,499] {process_utils.py:66} INFO - Process psutil.Process(pid=75, status='terminated', exitcode=1, started='15:55:24') (75) terminated with exit code 1
