[2023-04-02 17:03:19,425] {taskinstance.py:877} INFO - Dependencies all met for <TaskInstance: dag_weather_etl_v02.process_data 2023-04-01T00:00:00+00:00 [queued]>
[2023-04-02 17:03:19,446] {taskinstance.py:877} INFO - Dependencies all met for <TaskInstance: dag_weather_etl_v02.process_data 2023-04-01T00:00:00+00:00 [queued]>
[2023-04-02 17:03:19,447] {taskinstance.py:1068} INFO - 
--------------------------------------------------------------------------------
[2023-04-02 17:03:19,447] {taskinstance.py:1069} INFO - Starting attempt 1 of 6
[2023-04-02 17:03:19,448] {taskinstance.py:1070} INFO - 
--------------------------------------------------------------------------------
[2023-04-02 17:03:19,466] {taskinstance.py:1089} INFO - Executing <Task(_PythonDecoratedOperator): process_data> on 2023-04-01T00:00:00+00:00
[2023-04-02 17:03:19,479] {standard_task_runner.py:52} INFO - Started process 756 to run task
[2023-04-02 17:03:19,487] {standard_task_runner.py:76} INFO - Running: ['airflow', 'tasks', 'run', 'dag_weather_etl_v02', 'process_data', '2023-04-01T00:00:00+00:00', '--job-id', '197', '--pool', 'default_pool', '--raw', '--subdir', 'DAGS_FOLDER/dag_etl_weather.py', '--cfg-path', '/tmp/tmp0_py2i9h', '--error-file', '/tmp/tmpes4uoy4z']
[2023-04-02 17:03:19,490] {standard_task_runner.py:77} INFO - Job 197: Subtask process_data
[2023-04-02 17:03:19,562] {logging_mixin.py:104} INFO - Running <TaskInstance: dag_weather_etl_v02.process_data 2023-04-01T00:00:00+00:00 [running]> on host ab4c74a9709c
[2023-04-02 17:03:19,646] {taskinstance.py:1283} INFO - Exporting the following env vars:
AIRFLOW_CTX_DAG_OWNER=Mario
AIRFLOW_CTX_DAG_ID=dag_weather_etl_v02
AIRFLOW_CTX_TASK_ID=process_data
AIRFLOW_CTX_EXECUTION_DATE=2023-04-01T00:00:00+00:00
AIRFLOW_CTX_DAG_RUN_ID=scheduled__2023-04-01T00:00:00+00:00
[2023-04-02 17:03:20,091] {taskinstance.py:1482} ERROR - Task failed with exception
Traceback (most recent call last):
  File "/home/airflow/.local/lib/python3.6/site-packages/airflow/models/taskinstance.py", line 1138, in _run_raw_task
    self._prepare_and_execute_task_with_callbacks(context, task)
  File "/home/airflow/.local/lib/python3.6/site-packages/airflow/models/taskinstance.py", line 1311, in _prepare_and_execute_task_with_callbacks
    result = self._execute_task(context, task_copy)
  File "/home/airflow/.local/lib/python3.6/site-packages/airflow/models/taskinstance.py", line 1341, in _execute_task
    result = task_copy.execute(context=context)
  File "/home/airflow/.local/lib/python3.6/site-packages/airflow/operators/python.py", line 233, in execute
    return_value = self.python_callable(*self.op_args, **self.op_kwargs)
  File "/opt/airflow/dags/dag_etl_weather.py", line 39, in process_data
    .config("spark.sql.warehouse.dir", "/user/hive/warehouse")\
  File "/home/airflow/.local/lib/python3.6/site-packages/pyspark/sql/session.py", line 228, in getOrCreate
    sc = SparkContext.getOrCreate(sparkConf)
  File "/home/airflow/.local/lib/python3.6/site-packages/pyspark/context.py", line 392, in getOrCreate
    SparkContext(conf=conf or SparkConf())
  File "/home/airflow/.local/lib/python3.6/site-packages/pyspark/context.py", line 144, in __init__
    SparkContext._ensure_initialized(self, gateway=gateway, conf=conf)
  File "/home/airflow/.local/lib/python3.6/site-packages/pyspark/context.py", line 339, in _ensure_initialized
    SparkContext._gateway = gateway or launch_gateway(conf)
  File "/home/airflow/.local/lib/python3.6/site-packages/pyspark/java_gateway.py", line 108, in launch_gateway
    raise RuntimeError("Java gateway process exited before sending its port number")
RuntimeError: Java gateway process exited before sending its port number
[2023-04-02 17:03:20,097] {taskinstance.py:1532} INFO - Marking task as UP_FOR_RETRY. dag_id=dag_weather_etl_v02, task_id=process_data, execution_date=20230401T000000, start_date=20230402T170319, end_date=20230402T170320
[2023-04-02 17:03:20,151] {local_task_job.py:146} INFO - Task exited with return code 1
[2023-04-02 19:14:48,664] {taskinstance.py:877} INFO - Dependencies all met for <TaskInstance: dag_weather_etl_v02.process_data 2023-04-01T00:00:00+00:00 [queued]>
[2023-04-02 19:14:48,687] {taskinstance.py:877} INFO - Dependencies all met for <TaskInstance: dag_weather_etl_v02.process_data 2023-04-01T00:00:00+00:00 [queued]>
[2023-04-02 19:14:48,688] {taskinstance.py:1068} INFO - 
--------------------------------------------------------------------------------
[2023-04-02 19:14:48,688] {taskinstance.py:1069} INFO - Starting attempt 1 of 6
[2023-04-02 19:14:48,689] {taskinstance.py:1070} INFO - 
--------------------------------------------------------------------------------
[2023-04-02 19:14:48,698] {taskinstance.py:1089} INFO - Executing <Task(_PythonDecoratedOperator): process_data> on 2023-04-01T00:00:00+00:00
[2023-04-02 19:14:48,718] {standard_task_runner.py:52} INFO - Started process 8450 to run task
[2023-04-02 19:14:48,734] {standard_task_runner.py:76} INFO - Running: ['airflow', 'tasks', 'run', 'dag_weather_etl_v02', 'process_data', '2023-04-01T00:00:00+00:00', '--job-id', '255', '--pool', 'default_pool', '--raw', '--subdir', 'DAGS_FOLDER/dag_etl_weather.py', '--cfg-path', '/tmp/tmpdh8rvwmv', '--error-file', '/tmp/tmp0r19u8x2']
[2023-04-02 19:14:48,738] {standard_task_runner.py:77} INFO - Job 255: Subtask process_data
[2023-04-02 19:14:48,807] {logging_mixin.py:104} INFO - Running <TaskInstance: dag_weather_etl_v02.process_data 2023-04-01T00:00:00+00:00 [running]> on host b24fa9ddb366
[2023-04-02 19:14:48,867] {taskinstance.py:1283} INFO - Exporting the following env vars:
AIRFLOW_CTX_DAG_OWNER=Mario
AIRFLOW_CTX_DAG_ID=dag_weather_etl_v02
AIRFLOW_CTX_TASK_ID=process_data
AIRFLOW_CTX_EXECUTION_DATE=2023-04-01T00:00:00+00:00
AIRFLOW_CTX_DAG_RUN_ID=scheduled__2023-04-01T00:00:00+00:00
[2023-04-02 19:14:55,053] {logging_mixin.py:104} WARNING - /home/airflow/.local/lib/python3.6/site-packages/pyspark/context.py:238 FutureWarning: Python 3.6 support is deprecated in Spark 3.2.
[2023-04-02 19:14:56,582] {logging_mixin.py:104} INFO - There are NaN values in the data!
[2023-04-02 19:14:56,640] {logging_mixin.py:104} INFO - La fecha 02/04/2023 19:00 no tiene el formato correcto
[2023-04-02 19:14:56,642] {logging_mixin.py:104} INFO - La fecha 02/04/2023 18:00 no tiene el formato correcto
[2023-04-02 19:14:56,645] {logging_mixin.py:104} INFO - La fecha 02/04/2023 17:00 no tiene el formato correcto
[2023-04-02 19:14:56,646] {logging_mixin.py:104} INFO - La fecha 02/04/2023 16:00 no tiene el formato correcto
[2023-04-02 19:14:56,648] {logging_mixin.py:104} INFO - La fecha 02/04/2023 15:00 no tiene el formato correcto
[2023-04-02 19:14:56,651] {logging_mixin.py:104} INFO - La fecha 02/04/2023 14:00 no tiene el formato correcto
[2023-04-02 19:14:56,653] {logging_mixin.py:104} INFO - La fecha 02/04/2023 13:00 no tiene el formato correcto
[2023-04-02 19:14:56,656] {logging_mixin.py:104} INFO - La fecha 02/04/2023 12:00 no tiene el formato correcto
[2023-04-02 19:14:56,661] {logging_mixin.py:104} INFO - La fecha 02/04/2023 11:00 no tiene el formato correcto
[2023-04-02 19:14:56,663] {logging_mixin.py:104} INFO - La fecha 02/04/2023 10:00 no tiene el formato correcto
[2023-04-02 19:14:56,665] {logging_mixin.py:104} INFO - La fecha 02/04/2023 09:00 no tiene el formato correcto
[2023-04-02 19:14:56,667] {logging_mixin.py:104} INFO - La fecha 02/04/2023 08:00 no tiene el formato correcto
[2023-04-02 19:14:56,667] {logging_mixin.py:104} INFO - La fecha 02/04/2023 07:00 no tiene el formato correcto
[2023-04-02 19:14:56,668] {logging_mixin.py:104} INFO - La fecha 02/04/2023 06:00 no tiene el formato correcto
[2023-04-02 19:14:56,669] {logging_mixin.py:104} INFO - La fecha 02/04/2023 05:00 no tiene el formato correcto
[2023-04-02 19:14:56,669] {logging_mixin.py:104} INFO - La fecha 02/04/2023 04:00 no tiene el formato correcto
[2023-04-02 19:14:56,670] {logging_mixin.py:104} INFO - La fecha 02/04/2023 03:00 no tiene el formato correcto
[2023-04-02 19:14:56,671] {logging_mixin.py:104} INFO - La fecha 02/04/2023 02:00 no tiene el formato correcto
[2023-04-02 19:14:56,672] {logging_mixin.py:104} INFO - La fecha 02/04/2023 01:00 no tiene el formato correcto
[2023-04-02 19:14:56,672] {logging_mixin.py:104} INFO - La fecha 02/04/2023 00:00 no tiene el formato correcto
[2023-04-02 19:14:56,673] {logging_mixin.py:104} INFO - La fecha 01/04/2023 23:00 no tiene el formato correcto
[2023-04-02 19:14:56,673] {logging_mixin.py:104} INFO - La fecha 01/04/2023 22:00 no tiene el formato correcto
[2023-04-02 19:14:56,674] {logging_mixin.py:104} INFO - La fecha 01/04/2023 21:00 no tiene el formato correcto
[2023-04-02 19:14:56,675] {logging_mixin.py:104} INFO - La fecha 01/04/2023 20:00 no tiene el formato correcto
[2023-04-02 19:14:57,234] {logging_mixin.py:104} WARNING - Traceback (most recent call last):
[2023-04-02 19:14:57,236] {logging_mixin.py:104} WARNING -   File "/home/airflow/.local/lib/python3.6/site-packages/pyspark/serializers.py", line 437, in dumps
    return cloudpickle.dumps(obj, pickle_protocol)
[2023-04-02 19:14:57,236] {logging_mixin.py:104} WARNING -   File "/home/airflow/.local/lib/python3.6/site-packages/pyspark/cloudpickle/cloudpickle_fast.py", line 102, in dumps
    cp.dump(obj)
[2023-04-02 19:14:57,237] {logging_mixin.py:104} WARNING -   File "/home/airflow/.local/lib/python3.6/site-packages/pyspark/cloudpickle/cloudpickle_fast.py", line 563, in dump
    return Pickler.dump(self, obj)
[2023-04-02 19:14:57,238] {logging_mixin.py:104} WARNING -   File "/usr/local/lib/python3.6/pickle.py", line 409, in dump
    self.save(obj)
[2023-04-02 19:14:57,238] {logging_mixin.py:104} WARNING -   File "/usr/local/lib/python3.6/pickle.py", line 476, in save
    f(self, obj) # Call unbound method with explicit self
[2023-04-02 19:14:57,239] {logging_mixin.py:104} WARNING -   File "/usr/local/lib/python3.6/pickle.py", line 751, in save_tuple
    save(element)
[2023-04-02 19:14:57,239] {logging_mixin.py:104} WARNING -   File "/usr/local/lib/python3.6/pickle.py", line 476, in save
    f(self, obj) # Call unbound method with explicit self
[2023-04-02 19:14:57,240] {logging_mixin.py:104} WARNING -   File "/home/airflow/.local/lib/python3.6/site-packages/pyspark/cloudpickle/cloudpickle_fast.py", line 745, in save_function
    *self._dynamic_function_reduce(obj), obj=obj
[2023-04-02 19:14:57,240] {logging_mixin.py:104} WARNING -   File "/home/airflow/.local/lib/python3.6/site-packages/pyspark/cloudpickle/cloudpickle_fast.py", line 682, in _save_reduce_pickle5
    dictitems=dictitems, obj=obj
[2023-04-02 19:14:57,241] {logging_mixin.py:104} WARNING -   File "/usr/local/lib/python3.6/pickle.py", line 610, in save_reduce
    save(args)
[2023-04-02 19:14:57,241] {logging_mixin.py:104} WARNING -   File "/usr/local/lib/python3.6/pickle.py", line 476, in save
    f(self, obj) # Call unbound method with explicit self
[2023-04-02 19:14:57,242] {logging_mixin.py:104} WARNING -   File "/usr/local/lib/python3.6/pickle.py", line 751, in save_tuple
    save(element)
[2023-04-02 19:14:57,242] {logging_mixin.py:104} WARNING -   File "/usr/local/lib/python3.6/pickle.py", line 476, in save
    f(self, obj) # Call unbound method with explicit self
[2023-04-02 19:14:57,243] {logging_mixin.py:104} WARNING -   File "/usr/local/lib/python3.6/pickle.py", line 736, in save_tuple
    save(element)
[2023-04-02 19:14:57,243] {logging_mixin.py:104} WARNING -   File "/usr/local/lib/python3.6/pickle.py", line 476, in save
    f(self, obj) # Call unbound method with explicit self
[2023-04-02 19:14:57,243] {logging_mixin.py:104} WARNING -   File "/home/airflow/.local/lib/python3.6/site-packages/dill/_dill.py", line 1169, in save_cell
    f = obj.cell_contents
[2023-04-02 19:14:57,244] {logging_mixin.py:104} WARNING - ValueError: Cell is empty
[2023-04-02 19:14:57,245] {taskinstance.py:1482} ERROR - Task failed with exception
Traceback (most recent call last):
  File "/home/airflow/.local/lib/python3.6/site-packages/pyspark/serializers.py", line 437, in dumps
    return cloudpickle.dumps(obj, pickle_protocol)
  File "/home/airflow/.local/lib/python3.6/site-packages/pyspark/cloudpickle/cloudpickle_fast.py", line 102, in dumps
    cp.dump(obj)
  File "/home/airflow/.local/lib/python3.6/site-packages/pyspark/cloudpickle/cloudpickle_fast.py", line 563, in dump
    return Pickler.dump(self, obj)
  File "/usr/local/lib/python3.6/pickle.py", line 409, in dump
    self.save(obj)
  File "/usr/local/lib/python3.6/pickle.py", line 476, in save
    f(self, obj) # Call unbound method with explicit self
  File "/usr/local/lib/python3.6/pickle.py", line 751, in save_tuple
    save(element)
  File "/usr/local/lib/python3.6/pickle.py", line 476, in save
    f(self, obj) # Call unbound method with explicit self
  File "/home/airflow/.local/lib/python3.6/site-packages/pyspark/cloudpickle/cloudpickle_fast.py", line 745, in save_function
    *self._dynamic_function_reduce(obj), obj=obj
  File "/home/airflow/.local/lib/python3.6/site-packages/pyspark/cloudpickle/cloudpickle_fast.py", line 682, in _save_reduce_pickle5
    dictitems=dictitems, obj=obj
  File "/usr/local/lib/python3.6/pickle.py", line 610, in save_reduce
    save(args)
  File "/usr/local/lib/python3.6/pickle.py", line 476, in save
    f(self, obj) # Call unbound method with explicit self
  File "/usr/local/lib/python3.6/pickle.py", line 751, in save_tuple
    save(element)
  File "/usr/local/lib/python3.6/pickle.py", line 476, in save
    f(self, obj) # Call unbound method with explicit self
  File "/usr/local/lib/python3.6/pickle.py", line 736, in save_tuple
    save(element)
  File "/usr/local/lib/python3.6/pickle.py", line 476, in save
    f(self, obj) # Call unbound method with explicit self
  File "/home/airflow/.local/lib/python3.6/site-packages/dill/_dill.py", line 1169, in save_cell
    f = obj.cell_contents
ValueError: Cell is empty

During handling of the above exception, another exception occurred:

Traceback (most recent call last):
  File "/home/airflow/.local/lib/python3.6/site-packages/airflow/models/taskinstance.py", line 1138, in _run_raw_task
    self._prepare_and_execute_task_with_callbacks(context, task)
  File "/home/airflow/.local/lib/python3.6/site-packages/airflow/models/taskinstance.py", line 1311, in _prepare_and_execute_task_with_callbacks
    result = self._execute_task(context, task_copy)
  File "/home/airflow/.local/lib/python3.6/site-packages/airflow/models/taskinstance.py", line 1341, in _execute_task
    result = task_copy.execute(context=context)
  File "/home/airflow/.local/lib/python3.6/site-packages/airflow/operators/python.py", line 233, in execute
    return_value = self.python_callable(*self.op_args, **self.op_kwargs)
  File "/opt/airflow/dags/dag_etl_weather.py", line 85, in process_data
    spark_df = (spark.createDataFrame(datos_procesados))
  File "/home/airflow/.local/lib/python3.6/site-packages/pyspark/sql/session.py", line 674, in createDataFrame
    data, schema, samplingRatio, verifySchema)
  File "/home/airflow/.local/lib/python3.6/site-packages/pyspark/sql/pandas/conversion.py", line 340, in createDataFrame
    return self._create_dataframe(data, schema, samplingRatio, verifySchema)
  File "/home/airflow/.local/lib/python3.6/site-packages/pyspark/sql/session.py", line 701, in _create_dataframe
    jrdd = self._jvm.SerDeUtil.toJavaArray(rdd._to_java_object_rdd())
  File "/home/airflow/.local/lib/python3.6/site-packages/pyspark/rdd.py", line 2620, in _to_java_object_rdd
    return self.ctx._jvm.SerDeUtil.pythonToJava(rdd._jrdd, True)
  File "/home/airflow/.local/lib/python3.6/site-packages/pyspark/rdd.py", line 2952, in _jrdd
    self._jrdd_deserializer, profiler)
  File "/home/airflow/.local/lib/python3.6/site-packages/pyspark/rdd.py", line 2830, in _wrap_function
    pickled_command, broadcast_vars, env, includes = _prepare_for_python_RDD(sc, command)
  File "/home/airflow/.local/lib/python3.6/site-packages/pyspark/rdd.py", line 2816, in _prepare_for_python_RDD
    pickled_command = ser.dumps(command)
  File "/home/airflow/.local/lib/python3.6/site-packages/pyspark/serializers.py", line 447, in dumps
    raise pickle.PicklingError(msg)
_pickle.PicklingError: Could not serialize object: ValueError: Cell is empty
[2023-04-02 19:14:57,251] {taskinstance.py:1532} INFO - Marking task as UP_FOR_RETRY. dag_id=dag_weather_etl_v02, task_id=process_data, execution_date=20230401T000000, start_date=20230402T191448, end_date=20230402T191457
[2023-04-02 19:14:57,358] {local_task_job.py:146} INFO - Task exited with return code 1
