[2023-04-02 18:46:42,383] {taskinstance.py:877} INFO - Dependencies all met for <TaskInstance: dag_weather_etl_v02.process_data 2023-04-01T00:00:00+00:00 [queued]>
[2023-04-02 18:46:42,405] {taskinstance.py:877} INFO - Dependencies all met for <TaskInstance: dag_weather_etl_v02.process_data 2023-04-01T00:00:00+00:00 [queued]>
[2023-04-02 18:46:42,411] {taskinstance.py:1068} INFO - 
--------------------------------------------------------------------------------
[2023-04-02 18:46:42,415] {taskinstance.py:1069} INFO - Starting attempt 26 of 31
[2023-04-02 18:46:42,416] {taskinstance.py:1070} INFO - 
--------------------------------------------------------------------------------
[2023-04-02 18:46:42,435] {taskinstance.py:1089} INFO - Executing <Task(_PythonDecoratedOperator): process_data> on 2023-04-01T00:00:00+00:00
[2023-04-02 18:46:42,471] {standard_task_runner.py:52} INFO - Started process 3625 to run task
[2023-04-02 18:46:42,484] {standard_task_runner.py:76} INFO - Running: ['airflow', 'tasks', 'run', 'dag_weather_etl_v02', 'process_data', '2023-04-01T00:00:00+00:00', '--job-id', '223', '--pool', 'default_pool', '--raw', '--subdir', 'DAGS_FOLDER/dag_etl_weather.py', '--cfg-path', '/tmp/tmpr9q6vyur', '--error-file', '/tmp/tmprxematb4']
[2023-04-02 18:46:42,485] {standard_task_runner.py:77} INFO - Job 223: Subtask process_data
[2023-04-02 18:46:42,541] {logging_mixin.py:104} INFO - Running <TaskInstance: dag_weather_etl_v02.process_data 2023-04-01T00:00:00+00:00 [running]> on host b24fa9ddb366
[2023-04-02 18:46:42,594] {taskinstance.py:1283} INFO - Exporting the following env vars:
AIRFLOW_CTX_DAG_OWNER=Mario
AIRFLOW_CTX_DAG_ID=dag_weather_etl_v02
AIRFLOW_CTX_TASK_ID=process_data
AIRFLOW_CTX_EXECUTION_DATE=2023-04-01T00:00:00+00:00
AIRFLOW_CTX_DAG_RUN_ID=scheduled__2023-04-01T00:00:00+00:00
[2023-04-02 18:46:50,535] {logging_mixin.py:104} WARNING - /home/airflow/.local/lib/python3.6/site-packages/pyspark/context.py:238 FutureWarning: Python 3.6 support is deprecated in Spark 3.2.
[2023-04-02 18:46:52,953] {logging_mixin.py:104} INFO - There are NaN values in the data!
[2023-04-02 18:46:52,985] {logging_mixin.py:104} INFO - La fecha 2/4/223 19: no tiene el formato correcto
[2023-04-02 18:46:52,986] {logging_mixin.py:104} INFO - La fecha 2/4/223 18: no tiene el formato correcto
[2023-04-02 18:46:52,987] {logging_mixin.py:104} INFO - La fecha 2/4/223 17: no tiene el formato correcto
[2023-04-02 18:46:52,988] {logging_mixin.py:104} INFO - La fecha 2/4/223 16: no tiene el formato correcto
[2023-04-02 18:46:52,988] {logging_mixin.py:104} INFO - La fecha 2/4/223 15: no tiene el formato correcto
[2023-04-02 18:46:52,989] {logging_mixin.py:104} INFO - La fecha 2/4/223 14: no tiene el formato correcto
[2023-04-02 18:46:52,990] {logging_mixin.py:104} INFO - La fecha 2/4/223 13: no tiene el formato correcto
[2023-04-02 18:46:52,991] {logging_mixin.py:104} INFO - La fecha 2/4/223 12: no tiene el formato correcto
[2023-04-02 18:46:52,991] {logging_mixin.py:104} INFO - La fecha 2/4/223 11: no tiene el formato correcto
[2023-04-02 18:46:52,992] {logging_mixin.py:104} INFO - La fecha 2/4/223 1: no tiene el formato correcto
[2023-04-02 18:46:52,992] {logging_mixin.py:104} INFO - La fecha 2/4/223 9: no tiene el formato correcto
[2023-04-02 18:46:52,993] {logging_mixin.py:104} INFO - La fecha 2/4/223 8: no tiene el formato correcto
[2023-04-02 18:46:52,993] {logging_mixin.py:104} INFO - La fecha 2/4/223 7: no tiene el formato correcto
[2023-04-02 18:46:52,994] {logging_mixin.py:104} INFO - La fecha 2/4/223 6: no tiene el formato correcto
[2023-04-02 18:46:52,994] {logging_mixin.py:104} INFO - La fecha 2/4/223 5: no tiene el formato correcto
[2023-04-02 18:46:52,995] {logging_mixin.py:104} INFO - La fecha 2/4/223 4: no tiene el formato correcto
[2023-04-02 18:46:52,996] {logging_mixin.py:104} INFO - La fecha 2/4/223 3: no tiene el formato correcto
[2023-04-02 18:46:52,996] {logging_mixin.py:104} INFO - La fecha 2/4/223 2: no tiene el formato correcto
[2023-04-02 18:46:52,997] {logging_mixin.py:104} INFO - La fecha 2/4/223 1: no tiene el formato correcto
[2023-04-02 18:46:52,997] {logging_mixin.py:104} INFO - La fecha 2/4/223 : no tiene el formato correcto
[2023-04-02 18:46:52,998] {logging_mixin.py:104} INFO - La fecha 1/4/223 23: no tiene el formato correcto
[2023-04-02 18:46:52,999] {logging_mixin.py:104} INFO - La fecha 1/4/223 22: no tiene el formato correcto
[2023-04-02 18:46:52,999] {logging_mixin.py:104} INFO - La fecha 1/4/223 21: no tiene el formato correcto
[2023-04-02 18:46:53,000] {logging_mixin.py:104} INFO - La fecha 1/4/223 2: no tiene el formato correcto
[2023-04-02 18:46:53,696] {logging_mixin.py:104} WARNING - Traceback (most recent call last):
[2023-04-02 18:46:53,698] {logging_mixin.py:104} WARNING -   File "/home/airflow/.local/lib/python3.6/site-packages/pyspark/serializers.py", line 437, in dumps
    return cloudpickle.dumps(obj, pickle_protocol)
[2023-04-02 18:46:53,699] {logging_mixin.py:104} WARNING -   File "/home/airflow/.local/lib/python3.6/site-packages/pyspark/cloudpickle/cloudpickle_fast.py", line 102, in dumps
    cp.dump(obj)
[2023-04-02 18:46:53,699] {logging_mixin.py:104} WARNING -   File "/home/airflow/.local/lib/python3.6/site-packages/pyspark/cloudpickle/cloudpickle_fast.py", line 563, in dump
    return Pickler.dump(self, obj)
[2023-04-02 18:46:53,700] {logging_mixin.py:104} WARNING -   File "/usr/local/lib/python3.6/pickle.py", line 409, in dump
    self.save(obj)
[2023-04-02 18:46:53,701] {logging_mixin.py:104} WARNING -   File "/usr/local/lib/python3.6/pickle.py", line 476, in save
    f(self, obj) # Call unbound method with explicit self
[2023-04-02 18:46:53,702] {logging_mixin.py:104} WARNING -   File "/usr/local/lib/python3.6/pickle.py", line 751, in save_tuple
    save(element)
[2023-04-02 18:46:53,702] {logging_mixin.py:104} WARNING -   File "/usr/local/lib/python3.6/pickle.py", line 476, in save
    f(self, obj) # Call unbound method with explicit self
[2023-04-02 18:46:53,703] {logging_mixin.py:104} WARNING -   File "/home/airflow/.local/lib/python3.6/site-packages/pyspark/cloudpickle/cloudpickle_fast.py", line 745, in save_function
    *self._dynamic_function_reduce(obj), obj=obj
[2023-04-02 18:46:53,705] {logging_mixin.py:104} WARNING -   File "/home/airflow/.local/lib/python3.6/site-packages/pyspark/cloudpickle/cloudpickle_fast.py", line 682, in _save_reduce_pickle5
    dictitems=dictitems, obj=obj
[2023-04-02 18:46:53,708] {logging_mixin.py:104} WARNING -   File "/usr/local/lib/python3.6/pickle.py", line 610, in save_reduce
    save(args)
[2023-04-02 18:46:53,709] {logging_mixin.py:104} WARNING -   File "/usr/local/lib/python3.6/pickle.py", line 476, in save
    f(self, obj) # Call unbound method with explicit self
[2023-04-02 18:46:53,711] {logging_mixin.py:104} WARNING -   File "/usr/local/lib/python3.6/pickle.py", line 751, in save_tuple
    save(element)
[2023-04-02 18:46:53,713] {logging_mixin.py:104} WARNING -   File "/usr/local/lib/python3.6/pickle.py", line 476, in save
    f(self, obj) # Call unbound method with explicit self
[2023-04-02 18:46:53,715] {logging_mixin.py:104} WARNING -   File "/usr/local/lib/python3.6/pickle.py", line 736, in save_tuple
    save(element)
[2023-04-02 18:46:53,716] {logging_mixin.py:104} WARNING -   File "/usr/local/lib/python3.6/pickle.py", line 476, in save
    f(self, obj) # Call unbound method with explicit self
[2023-04-02 18:46:53,718] {logging_mixin.py:104} WARNING -   File "/home/airflow/.local/lib/python3.6/site-packages/dill/_dill.py", line 1169, in save_cell
    f = obj.cell_contents
[2023-04-02 18:46:53,720] {logging_mixin.py:104} WARNING - ValueError: Cell is empty
[2023-04-02 18:46:53,724] {taskinstance.py:1482} ERROR - Task failed with exception
Traceback (most recent call last):
  File "/home/airflow/.local/lib/python3.6/site-packages/pyspark/serializers.py", line 437, in dumps
    return cloudpickle.dumps(obj, pickle_protocol)
  File "/home/airflow/.local/lib/python3.6/site-packages/pyspark/cloudpickle/cloudpickle_fast.py", line 102, in dumps
    cp.dump(obj)
  File "/home/airflow/.local/lib/python3.6/site-packages/pyspark/cloudpickle/cloudpickle_fast.py", line 563, in dump
    return Pickler.dump(self, obj)
  File "/usr/local/lib/python3.6/pickle.py", line 409, in dump
    self.save(obj)
  File "/usr/local/lib/python3.6/pickle.py", line 476, in save
    f(self, obj) # Call unbound method with explicit self
  File "/usr/local/lib/python3.6/pickle.py", line 751, in save_tuple
    save(element)
  File "/usr/local/lib/python3.6/pickle.py", line 476, in save
    f(self, obj) # Call unbound method with explicit self
  File "/home/airflow/.local/lib/python3.6/site-packages/pyspark/cloudpickle/cloudpickle_fast.py", line 745, in save_function
    *self._dynamic_function_reduce(obj), obj=obj
  File "/home/airflow/.local/lib/python3.6/site-packages/pyspark/cloudpickle/cloudpickle_fast.py", line 682, in _save_reduce_pickle5
    dictitems=dictitems, obj=obj
  File "/usr/local/lib/python3.6/pickle.py", line 610, in save_reduce
    save(args)
  File "/usr/local/lib/python3.6/pickle.py", line 476, in save
    f(self, obj) # Call unbound method with explicit self
  File "/usr/local/lib/python3.6/pickle.py", line 751, in save_tuple
    save(element)
  File "/usr/local/lib/python3.6/pickle.py", line 476, in save
    f(self, obj) # Call unbound method with explicit self
  File "/usr/local/lib/python3.6/pickle.py", line 736, in save_tuple
    save(element)
  File "/usr/local/lib/python3.6/pickle.py", line 476, in save
    f(self, obj) # Call unbound method with explicit self
  File "/home/airflow/.local/lib/python3.6/site-packages/dill/_dill.py", line 1169, in save_cell
    f = obj.cell_contents
ValueError: Cell is empty

During handling of the above exception, another exception occurred:

Traceback (most recent call last):
  File "/home/airflow/.local/lib/python3.6/site-packages/airflow/models/taskinstance.py", line 1138, in _run_raw_task
    self._prepare_and_execute_task_with_callbacks(context, task)
  File "/home/airflow/.local/lib/python3.6/site-packages/airflow/models/taskinstance.py", line 1311, in _prepare_and_execute_task_with_callbacks
    result = self._execute_task(context, task_copy)
  File "/home/airflow/.local/lib/python3.6/site-packages/airflow/models/taskinstance.py", line 1341, in _execute_task
    result = task_copy.execute(context=context)
  File "/home/airflow/.local/lib/python3.6/site-packages/airflow/operators/python.py", line 233, in execute
    return_value = self.python_callable(*self.op_args, **self.op_kwargs)
  File "/opt/airflow/dags/dag_etl_weather.py", line 72, in process_data
    spark_df = spark.createDataFrame(datos_procesados)
  File "/home/airflow/.local/lib/python3.6/site-packages/pyspark/sql/session.py", line 674, in createDataFrame
    data, schema, samplingRatio, verifySchema)
  File "/home/airflow/.local/lib/python3.6/site-packages/pyspark/sql/pandas/conversion.py", line 340, in createDataFrame
    return self._create_dataframe(data, schema, samplingRatio, verifySchema)
  File "/home/airflow/.local/lib/python3.6/site-packages/pyspark/sql/session.py", line 701, in _create_dataframe
    jrdd = self._jvm.SerDeUtil.toJavaArray(rdd._to_java_object_rdd())
  File "/home/airflow/.local/lib/python3.6/site-packages/pyspark/rdd.py", line 2620, in _to_java_object_rdd
    return self.ctx._jvm.SerDeUtil.pythonToJava(rdd._jrdd, True)
  File "/home/airflow/.local/lib/python3.6/site-packages/pyspark/rdd.py", line 2952, in _jrdd
    self._jrdd_deserializer, profiler)
  File "/home/airflow/.local/lib/python3.6/site-packages/pyspark/rdd.py", line 2830, in _wrap_function
    pickled_command, broadcast_vars, env, includes = _prepare_for_python_RDD(sc, command)
  File "/home/airflow/.local/lib/python3.6/site-packages/pyspark/rdd.py", line 2816, in _prepare_for_python_RDD
    pickled_command = ser.dumps(command)
  File "/home/airflow/.local/lib/python3.6/site-packages/pyspark/serializers.py", line 447, in dumps
    raise pickle.PicklingError(msg)
_pickle.PicklingError: Could not serialize object: ValueError: Cell is empty
[2023-04-02 18:46:53,736] {taskinstance.py:1532} INFO - Marking task as UP_FOR_RETRY. dag_id=dag_weather_etl_v02, task_id=process_data, execution_date=20230401T000000, start_date=20230402T184642, end_date=20230402T184653
[2023-04-02 18:46:53,858] {local_task_job.py:146} INFO - Task exited with return code 1
