[2023-04-02 18:49:07,961] {taskinstance.py:877} INFO - Dependencies all met for <TaskInstance: dag_weather_etl_v02.process_data 2023-04-02T18:49:06.592758+00:00 [queued]>
[2023-04-02 18:49:07,975] {taskinstance.py:877} INFO - Dependencies all met for <TaskInstance: dag_weather_etl_v02.process_data 2023-04-02T18:49:06.592758+00:00 [queued]>
[2023-04-02 18:49:07,976] {taskinstance.py:1068} INFO - 
--------------------------------------------------------------------------------
[2023-04-02 18:49:07,976] {taskinstance.py:1069} INFO - Starting attempt 1 of 6
[2023-04-02 18:49:07,977] {taskinstance.py:1070} INFO - 
--------------------------------------------------------------------------------
[2023-04-02 18:49:07,983] {taskinstance.py:1089} INFO - Executing <Task(_PythonDecoratedOperator): process_data> on 2023-04-02T18:49:06.592758+00:00
[2023-04-02 18:49:07,994] {standard_task_runner.py:52} INFO - Started process 3923 to run task
[2023-04-02 18:49:08,000] {standard_task_runner.py:76} INFO - Running: ['airflow', 'tasks', 'run', 'dag_weather_etl_v02', 'process_data', '2023-04-02T18:49:06.592758+00:00', '--job-id', '225', '--pool', 'default_pool', '--raw', '--subdir', 'DAGS_FOLDER/dag_etl_weather.py', '--cfg-path', '/tmp/tmp1k5pxyqn', '--error-file', '/tmp/tmp5cc0kgwq']
[2023-04-02 18:49:08,001] {standard_task_runner.py:77} INFO - Job 225: Subtask process_data
[2023-04-02 18:49:08,060] {logging_mixin.py:104} INFO - Running <TaskInstance: dag_weather_etl_v02.process_data 2023-04-02T18:49:06.592758+00:00 [running]> on host b24fa9ddb366
[2023-04-02 18:49:08,098] {taskinstance.py:1283} INFO - Exporting the following env vars:
AIRFLOW_CTX_DAG_OWNER=Mario
AIRFLOW_CTX_DAG_ID=dag_weather_etl_v02
AIRFLOW_CTX_TASK_ID=process_data
AIRFLOW_CTX_EXECUTION_DATE=2023-04-02T18:49:06.592758+00:00
AIRFLOW_CTX_DAG_RUN_ID=manual__2023-04-02T18:49:06.592758+00:00
[2023-04-02 18:49:15,528] {logging_mixin.py:104} WARNING - /home/airflow/.local/lib/python3.6/site-packages/pyspark/context.py:238 FutureWarning: Python 3.6 support is deprecated in Spark 3.2.
[2023-04-02 18:49:18,000] {logging_mixin.py:104} INFO - There are NaN values in the data!
[2023-04-02 18:49:18,049] {logging_mixin.py:104} INFO - La fecha 02/04/2023 19:00 no tiene el formato correcto
[2023-04-02 18:49:18,050] {logging_mixin.py:104} INFO - La fecha 02/04/2023 18:00 no tiene el formato correcto
[2023-04-02 18:49:18,051] {logging_mixin.py:104} INFO - La fecha 02/04/2023 17:00 no tiene el formato correcto
[2023-04-02 18:49:18,052] {logging_mixin.py:104} INFO - La fecha 02/04/2023 16:00 no tiene el formato correcto
[2023-04-02 18:49:18,052] {logging_mixin.py:104} INFO - La fecha 02/04/2023 15:00 no tiene el formato correcto
[2023-04-02 18:49:18,053] {logging_mixin.py:104} INFO - La fecha 02/04/2023 14:00 no tiene el formato correcto
[2023-04-02 18:49:18,054] {logging_mixin.py:104} INFO - La fecha 02/04/2023 13:00 no tiene el formato correcto
[2023-04-02 18:49:18,055] {logging_mixin.py:104} INFO - La fecha 02/04/2023 12:00 no tiene el formato correcto
[2023-04-02 18:49:18,055] {logging_mixin.py:104} INFO - La fecha 02/04/2023 11:00 no tiene el formato correcto
[2023-04-02 18:49:18,056] {logging_mixin.py:104} INFO - La fecha 02/04/2023 10:00 no tiene el formato correcto
[2023-04-02 18:49:18,057] {logging_mixin.py:104} INFO - La fecha 02/04/2023 09:00 no tiene el formato correcto
[2023-04-02 18:49:18,057] {logging_mixin.py:104} INFO - La fecha 02/04/2023 08:00 no tiene el formato correcto
[2023-04-02 18:49:18,058] {logging_mixin.py:104} INFO - La fecha 02/04/2023 07:00 no tiene el formato correcto
[2023-04-02 18:49:18,058] {logging_mixin.py:104} INFO - La fecha 02/04/2023 06:00 no tiene el formato correcto
[2023-04-02 18:49:18,059] {logging_mixin.py:104} INFO - La fecha 02/04/2023 05:00 no tiene el formato correcto
[2023-04-02 18:49:18,060] {logging_mixin.py:104} INFO - La fecha 02/04/2023 04:00 no tiene el formato correcto
[2023-04-02 18:49:18,060] {logging_mixin.py:104} INFO - La fecha 02/04/2023 03:00 no tiene el formato correcto
[2023-04-02 18:49:18,061] {logging_mixin.py:104} INFO - La fecha 02/04/2023 02:00 no tiene el formato correcto
[2023-04-02 18:49:18,061] {logging_mixin.py:104} INFO - La fecha 02/04/2023 01:00 no tiene el formato correcto
[2023-04-02 18:49:18,062] {logging_mixin.py:104} INFO - La fecha 02/04/2023 00:00 no tiene el formato correcto
[2023-04-02 18:49:18,062] {logging_mixin.py:104} INFO - La fecha 01/04/2023 23:00 no tiene el formato correcto
[2023-04-02 18:49:18,063] {logging_mixin.py:104} INFO - La fecha 01/04/2023 22:00 no tiene el formato correcto
[2023-04-02 18:49:18,064] {logging_mixin.py:104} INFO - La fecha 01/04/2023 21:00 no tiene el formato correcto
[2023-04-02 18:49:18,064] {logging_mixin.py:104} INFO - La fecha 01/04/2023 20:00 no tiene el formato correcto
[2023-04-02 18:49:18,108] {taskinstance.py:1482} ERROR - Task failed with exception
Traceback (most recent call last):
  File "/home/airflow/.local/lib/python3.6/site-packages/airflow/models/taskinstance.py", line 1138, in _run_raw_task
    self._prepare_and_execute_task_with_callbacks(context, task)
  File "/home/airflow/.local/lib/python3.6/site-packages/airflow/models/taskinstance.py", line 1311, in _prepare_and_execute_task_with_callbacks
    result = self._execute_task(context, task_copy)
  File "/home/airflow/.local/lib/python3.6/site-packages/airflow/models/taskinstance.py", line 1341, in _execute_task
    result = task_copy.execute(context=context)
  File "/home/airflow/.local/lib/python3.6/site-packages/airflow/operators/python.py", line 233, in execute
    return_value = self.python_callable(*self.op_args, **self.op_kwargs)
  File "/opt/airflow/dags/dag_etl_weather.py", line 72, in process_data
    spark_df = spark.createDataFrame(datos_procesados)
  File "/home/airflow/.local/lib/python3.6/site-packages/pyspark/sql/session.py", line 674, in createDataFrame
    data, schema, samplingRatio, verifySchema)
  File "/home/airflow/.local/lib/python3.6/site-packages/pyspark/sql/pandas/conversion.py", line 340, in createDataFrame
    return self._create_dataframe(data, schema, samplingRatio, verifySchema)
  File "/home/airflow/.local/lib/python3.6/site-packages/pyspark/sql/session.py", line 700, in _create_dataframe
    rdd, schema = self._createFromLocal(map(prepare, data), schema)
  File "/home/airflow/.local/lib/python3.6/site-packages/pyspark/sql/session.py", line 512, in _createFromLocal
    struct = self._inferSchemaFromList(data, names=schema)
  File "/home/airflow/.local/lib/python3.6/site-packages/pyspark/sql/session.py", line 439, in _inferSchemaFromList
    schema = reduce(_merge_type, (_infer_schema(row, names) for row in data))
  File "/home/airflow/.local/lib/python3.6/site-packages/pyspark/sql/types.py", line 1111, in _merge_type
    for f in a.fields]
  File "/home/airflow/.local/lib/python3.6/site-packages/pyspark/sql/types.py", line 1111, in <listcomp>
    for f in a.fields]
  File "/home/airflow/.local/lib/python3.6/site-packages/pyspark/sql/types.py", line 1104, in _merge_type
    raise TypeError(new_msg("Can not merge type %s and %s" % (type(a), type(b))))
TypeError: field Tendencia_hPa: Can not merge type <class 'pyspark.sql.types.DoubleType'> and <class 'pyspark.sql.types.StringType'>
[2023-04-02 18:49:18,120] {taskinstance.py:1532} INFO - Marking task as UP_FOR_RETRY. dag_id=dag_weather_etl_v02, task_id=process_data, execution_date=20230402T184906, start_date=20230402T184907, end_date=20230402T184918
[2023-04-02 18:49:18,241] {local_task_job.py:188} WARNING - State of this instance has been externally set to up_for_retry. Terminating instance.
[2023-04-02 18:49:18,288] {process_utils.py:100} INFO - Sending Signals.SIGTERM to GPID 3923
[2023-04-02 18:49:18,294] {process_utils.py:66} INFO - Process psutil.Process(pid=3923, status='terminated', exitcode=1, started='18:49:07') (3923) terminated with exit code 1
