[2023-03-25 19:03:38,782] {taskinstance.py:877} INFO - Dependencies all met for <TaskInstance: dag_python_operator_v5.greet 2023-03-25T19:03:35.925389+00:00 [queued]>
[2023-03-25 19:03:38,795] {taskinstance.py:877} INFO - Dependencies all met for <TaskInstance: dag_python_operator_v5.greet 2023-03-25T19:03:35.925389+00:00 [queued]>
[2023-03-25 19:03:38,796] {taskinstance.py:1068} INFO - 
--------------------------------------------------------------------------------
[2023-03-25 19:03:38,796] {taskinstance.py:1069} INFO - Starting attempt 1 of 6
[2023-03-25 19:03:38,796] {taskinstance.py:1070} INFO - 
--------------------------------------------------------------------------------
[2023-03-25 19:03:38,802] {taskinstance.py:1089} INFO - Executing <Task(PythonOperator): greet> on 2023-03-25T19:03:35.925389+00:00
[2023-03-25 19:03:38,806] {standard_task_runner.py:52} INFO - Started process 77 to run task
[2023-03-25 19:03:38,811] {standard_task_runner.py:76} INFO - Running: ['airflow', 'tasks', 'run', 'dag_python_operator_v5', 'greet', '2023-03-25T19:03:35.925389+00:00', '--job-id', '16', '--pool', 'default_pool', '--raw', '--subdir', 'DAGS_FOLDER/create_dag_with_python_operator.py', '--cfg-path', '/tmp/tmp87tlm4t0', '--error-file', '/tmp/tmpfml1yqkl']
[2023-03-25 19:03:38,812] {standard_task_runner.py:77} INFO - Job 16: Subtask greet
[2023-03-25 19:03:38,853] {logging_mixin.py:104} INFO - Running <TaskInstance: dag_python_operator_v5.greet 2023-03-25T19:03:35.925389+00:00 [running]> on host 087d02d74a34
[2023-03-25 19:03:38,887] {taskinstance.py:1283} INFO - Exporting the following env vars:
AIRFLOW_CTX_DAG_OWNER=Mario
AIRFLOW_CTX_DAG_ID=dag_python_operator_v5
AIRFLOW_CTX_TASK_ID=greet
AIRFLOW_CTX_EXECUTION_DATE=2023-03-25T19:03:35.925389+00:00
AIRFLOW_CTX_DAG_RUN_ID=manual__2023-03-25T19:03:35.925389+00:00
[2023-03-25 19:03:38,889] {taskinstance.py:1482} ERROR - Task failed with exception
Traceback (most recent call last):
  File "/home/airflow/.local/lib/python3.6/site-packages/airflow/models/taskinstance.py", line 1138, in _run_raw_task
    self._prepare_and_execute_task_with_callbacks(context, task)
  File "/home/airflow/.local/lib/python3.6/site-packages/airflow/models/taskinstance.py", line 1311, in _prepare_and_execute_task_with_callbacks
    result = self._execute_task(context, task_copy)
  File "/home/airflow/.local/lib/python3.6/site-packages/airflow/models/taskinstance.py", line 1341, in _execute_task
    result = task_copy.execute(context=context)
  File "/home/airflow/.local/lib/python3.6/site-packages/airflow/operators/python.py", line 117, in execute
    return_value = self.execute_callable()
  File "/home/airflow/.local/lib/python3.6/site-packages/airflow/operators/python.py", line 128, in execute_callable
    return self.python_callable(*self.op_args, **self.op_kwargs)
TypeError: greet() missing 1 required positional argument: 'age'
[2023-03-25 19:03:38,895] {taskinstance.py:1532} INFO - Marking task as UP_FOR_RETRY. dag_id=dag_python_operator_v5, task_id=greet, execution_date=20230325T190335, start_date=20230325T190338, end_date=20230325T190338
[2023-03-25 19:03:38,950] {local_task_job.py:146} INFO - Task exited with return code 1
